Workbook

Sheet y+ calculator
A1: Sim Name | B1: MaxVelocity, V, (m/s) | C1: Span, L, (m) | D1: Dynamic viscosity, mu, (Pa.s) | E1: Density, p, (kg/m^3) | F1: Reynolds number, Re | G1: Boundary layer thickness, | H1: y+ (wanted) | I1: deltaY1 | J1: Actual Y+ (max) | K1: Global element size
A2: Mesh 1, Simulation 1 - Final 2D 50c | B2: 1.57 | C2: 0.007537 | D2: 0.0035 | E2: 1060 | F2: =(B2*C2*E2)/D2 -> 3583.7358 | H2: 1 | I2: =2*H2*SQRT(74)*C2*F2^(-13/14) -> 6.4921646e-05 | J2: 6.27 | L2: NOTE: This is the initial simulation, will use 'actual Y+
A5: Calculating new DeltaY1 | B5: Old Delta Y1 | C5: Actual Y+ | D5: new delta Y1
B6: =I2 -> 6.4921646e-05 | C6: =J2 -> 6.27 | D6: =B6/C6 -> 1.035433e-05

Sheet Inflation height calculator
A1: First Layer Height (h_1), m | B1: Growth Rate (r) | C1: layer number (n) | D1: Height of layer number (h_n) | E1: Total inflation thickness or Sum of Layers (h_total), m | G1: Element Size
A2: 4e-05 | B2: 1.2 | C2: 10 | D2: =A2*(B2^(C2-1)) -> 0.00020639121 | E2: =A2*((B2^C2-1)/(B2-1)) -> 0.0010383473 | G2: =E2* SQRT(2) -> 0.0014684448
A3: 1.04e-05 | B3: 1.2 | C3: 10 | D3: =A3*(B3^(C3-1)) -> 5.3661716e-05 | E3: =A3*((B3^C3-1)/(B3-1)) -> 0.00026997029 | G3: =E3* SQRT(2) -> 0.00038179565
A13: Element size | B13: Height of layer number (h_n) | D13: growth rate ® | E13: number of layers (n) | F13: First layer height (h_1) | K13: Refinement Ratio
A14: 0.00025 | B14: =A14/SQRT(2) -> 0.0001767767 | D14: 1.2 | E14: 12 | F14: =B14/(D14^(E14-1)) -> 2.3792019e-05 | K14: 1.5
A16: 0.0001 | B16: =A16/SQRT(2) -> 7.0710678e-05 | D16: 1.1 | E16: 17 | F16: =B16/(D16^(E16-1)) -> 1.5388704e-05 | H16: VALVE | I16: BASE
A17: 0.0002 | B17: =A17/SQRT(2) -> 0.00014142136 | D17: 1.1 | E17: 15 | F17: =B17/(D17^(E17-1)) -> 3.7240663e-05 | H17: GLOBAL
A18: =A16/K14 -> 6.6666667e-05 | B18: =A18/SQRT(2) -> 4.7140452e-05 | D18: 1.1 | E18: 17 | F18: =B18/(D18^(E18-1)) -> 1.0259136e-05 | H18: VALVE | I18: Ref +1
A19: =A17/K14 -> 0.00013333333 | B19: =A19/SQRT(2) -> 9.4280904e-05 | D19: 1.1 | E19: 17 | F19: =B19/(D19^(E19-1)) -> 2.0518272e-05 | H19: GLOBAL
A20: =A16*$K$14 -> 0.00015 | B20: =A20/SQRT(2) -> 0.00010606602 | D20: 1.1 | E20: 17 | F20: =B20/(D20^(E20-1)) -> 2.3083056e-05 | H20: VALVE | I20: Coarse + 1
A21: =A17*$K$14 -> 0.0003 | B21: =A21/SQRT(2) -> 0.00021213203 | D21: 1.1 | E21: 14 | F21: =B21/(D21^(E21-1)) -> 6.1447094e-05 | H21: GLOBAL
A22: =A20*$K$14 -> 0.000225 | B22: =A22/SQRT(2) -> 0.00015909903 | D22: 1.1 | E22: 17 | F22: =B22/(D22^(E22-1)) -> 3.4624583e-05 | H22: VALVE | I22: Coarse + 2
A23: =A21*$K$14 -> 0.00045 | B23: =A23/SQRT(2) -> 0.00031819805 | D23: 1.1 | E23: 17 | F23: =B23/(D23^(E23-1)) -> 6.9249167e-05 | H23: GLOBAL
A24: =A22*$K$14 -> 0.0003375 | B24: =A24/SQRT(2) -> 0.00023864854 | D24: 1.1 | E24: 17 | F24: =B24/(D24^(E24-1)) -> 5.1936875e-05 | H24: VALVE | I24: Coarse + 3
A25: =A23*$K$14 -> 0.000675 | B25: =A25/SQRT(2) -> 0.00047729708 | D25: 1.1 | E25: 17 | F25: =B25/(D25^(E25-1)) -> 0.00010387375 | H25: GLOBAL
A26: =A24*$K$14 -> 0.00050625 | B26: =A26/SQRT(2) -> 0.00035797281 | D26: 1.1 | E26: 17 | F26: =B26/(D26^(E26-1)) -> 7.7905313e-05 | H26: VALVE | I26: Coarse + 4
A27: =A25*$K$14 -> 0.0010125 | B27: =A27/SQRT(2) -> 0.00071594562 | D27: 1.1 | E27: 15 | F27: =B27/(D27^(E27-1)) -> 0.00018853086 | H27: GLOBAL

Sheet 2D Base Ref
G6: delta_3 | H6: delta_2 | I6: delta_1
D7: Coarse -4 | E7: Coarse -3 | F7: Coarse + 2 | G7: Coarse + 1 | H7: BASE | I7: Ref +1 | J7: Ref +2
B8: Global | C8: Element Size | E8: 0.000675 | F8: 0.00045 | G8: 0.0003 | H8: 0.0002 | I8: ='Inflation height calculator'!A19 -> 0.00013333333 | J8: =I8/1.5 -> 8.8888889e-05 | K8: m
C9: First Layer Height | E9: 0.0001 | F9: 3e-05 | G9: 3e-05 | H9: 3.4e-05 | I9: ='Inflation height calculator'!F19 -> 2.0518272e-05
C10: Maximum Layer | E10: 17 | F10: 17 | G10: 17 | H10: 17 | I10: ='Inflation height calculator'!E19 -> 17
C11: Growth Rate | E11: 1.1 | F11: 1.1 | G11: 1.1 | H11: 1.1 | I11: ='Inflation height calculator'!D19 -> 1.1
B12: Local Refinement | C12: Element Size | E12: 0.000375 | F12: 0.000225 | G12: 0.00015 | H12: 0.0001 | I12: ='Inflation height calculator'!A18 -> 6.6666667e-05 | J12: =J8/SQRT(2) -> 6.2853936e-05 | K12: m
C13: First Layer Height | E13: 5.2e-05 | F13: 3.46e-05 | G13: 2.31e-05 | H13: 1.84e-05 | I13: ='Inflation height calculator'!F18 -> 1.0259136e-05
C14: Maximum Layer | E14: 17 | F14: 17 | G14: 17 | H14: 17 | I14: ='Inflation height calculator'!E18 -> 17
C15: Growth Rate | E15: 1.1 | F15: 1.1 | G15: 1.1 | H15: 1.1 | I15: ='Inflation height calculator'!D18 -> 1.1
B16: Results | C16: yplusval | D16: 0.612426 | E16: 0.428618 | F16: 0.133294 | G16: 0.10509 | H16: 0.152187 | I16: 0.0852505
C17: YplusMax | D17: 6.70864 | E17: 4.73265 | F17: 5.10089 | G17: 3.67753 | H17: 1.87096 | I17: 1.30188
C18: WallShearMax | D18: 36.6627 | E18: 48.25 | F18: 71.8155 | G18: 146.569 | H18: 123.958 | I18: 169.496 | K18: Pa
C19: WallShearAvg | D19: 1.41089 | E19: 1.77311 | F19: 1.49683 | G19: 1.5101 | H19: 1.8588 | I19: 1.7731 | K19: Pa
C20: VelocityAvg | D20: 0.438513 | E20: 0.437404 | F20: 0.43781 | G20: 0.436106 | H20: 0.438827 | I20: 0.440562 | K20: m s^-1
C21: VelocityMax | D21: 1.66348 | E21: 1.68584 | F21: 1.72878 | G21: 1.72507 | H21: 1.73045 | I21: 1.72616 | K21: m s^-1
C22: PressureAvg | D22: 14189.6 | E22: 14204 | F22: 14227.2 | G22: 14247.6 | H22: 14258.7 | I22: 14259.7 | K22: Pa
C23: PressureMax | D23: 15655 | E23: 15806.8 | F23: 16097.9 | G23: 16286.3 | H23: 16415.2 | I23: 16745.5 | K23: Pa
C24: Mesh Elements | D24: 7501 | E24: 13667 | F24: 33837 | G24: 69513 | H24: 150118 | I24: 334579
C25: Sim Duration | E25: 7:13 | F25: 10:30 | G25: 12:10 | H25: 20 | I25: 40:37 | K25: mins:secs
B32: Results | C32: yplusval | D32: 0.038349 | E32: 0.0570509 | F32: 0.0814175 | G32: 0.108798 | H32: 0.152187 | I32: 0.214102 | J32: 0.256261 | M32: where phi = my variable of interest
C33: YplusMax | D33: 1.64262 | E33: 1.6867 | F33: 1.78821 | G33: 1.85168 | H33: 1.87096 | I33: 2.02596 | J33: 1.98565
C34: WallShearMax | D34: 89.4128 | E34: 94.2542 | F34: 104.269 | G34: 108.606 | H34: 123.958 | I34: 131.237 | J34: 155.94
C35: WallShearAvg | D35: 0.449309 | E35: 0.677267 | F35: 0.977328 | G35: 1.32493 | H35: 1.8588 | I35: 2.45491 | J35: 3.15022
C36: VelocityAvg | D36: 0.440177 | E36: 0.438389 | F36: 0.436904 | G36: 0.43625 | H36: 0.438827 | I36: 0.440758 | J36: 0.438103
C37: VelocityMax | D37: 1.64661 | E37: 1.67414 | F37: 1.71726 | G37: 1.72267 | H37: 1.73045 | I37: 1.72846 | J37: 1.73128
C38: PressureAvg | D38: 14185.7 | E38: 14207.9 | F38: 14234.3 | G38: 14246.1 | H38: 14258.7 | I38: 14259.5 | J38: 14264.7
C39: PressureMax | D39: 15742.1 | E39: 15928.4 | F39: 16093.1 | G39: 16263.1 | H39: 16415.2 | I39: 16542.3 | J39: 16895.4
C40: Mesh Elements | D40: 9977 | E40: 16977 | F40: 36185 | G40: 70700 | H40: 150118 | I40: 265271 | J40: 695470
D41: 0.0012652315 | E41: 2: 35.229 | F41: 4: 59.159 | G41: 0.0081376852 | I41: 0.020167789 | J41: 0.032287616
C43: No# Nodes | D43: 15342 | E43: 24822 | F43: 48984 | G43: 89744 | H43: 179546 | I43: 379362
C44: Processed No# Nodes | D44: =(1/D43)/(10^-6) -> 65.18055 | E44: =(1/E43)/(10^-6) -> 40.286842 | F44: =(1/F43)/(10^-6) -> 20.414829 | G44: =(1/G43)/(10^-6) -> 11.142806 | H44: =(1/H43)/(10^-6) -> 5.5696033 | I44: =(1/I43)/(10^-6) -> 2.6360047
D45: 1.64661 | E45: 1.67414 | F45: 1.71726 | G45: 1.72267 | H45: 1.73045 | I45: 1.72846
C48: Coarse 1-3 | D48: BASE - Coarse 2 | E48: Ref +1 - Coarse 1
B49: r | C49: 1.5
B50: phi_1 | C50: =G37 -> 1.72267 | D50: =H37 -> 1.73045 | E50: =I37 -> 1.72846
B51: phi_2 | C51: =F37 -> 1.71726 | D51: =G37 -> 1.72267 | E51: =H37 -> 1.73045
B52: phi_3 | C52: =E37 -> 1.67414 | D52: =F37 -> 1.71726 | E52: =G37 -> 1.72267
B53: p | C53: =(LN((C52-C51)/(C51-C50)))/(LN($C$49)) -> 5.1193994 | D53: =(LN((D52-D51)/(D51-D50)))/(LN($C$49)) -> -0.89602592 | E53: =(LN((E52-E51)/(E51-E50)))/(LN($C$49)) -> #NUM! | G53: There may be errors with the finer meshes, maybe due to element quality at some points that cause an invalid p number
B55: Richardson Point | C55: =C50+((C50-C51)/($C$49^C53 - 1)) -> 1.7234461 | D55: =D50+((D50-D51)/($C$49^D53 - 1)) -> 1.7049106 | E55: =E50+((E50-E51)/($C$49^E53 - 1)) -> #NUM!
...

Sheet 3D Mesh Analysis
D2: Inflation Parameters
B3: Global Inflation | C3: First Layer Height | D3: 3e-05
C4: Maximum Layer | D4: 17
C5: Growth Rate | D5: 1.1 | H5: Grid reduction ratio
B6: Local Inflation | C6: First Layer Height | D6: 1.84e-05 | H6: 2
C7: Maximum Layer | D7: 17
C8: Growth Rate | D8: 1.1 | J8: where phi = my variable of interest
D11: BASE -1 coarse | E11: BASE 3D 50cc | F11: BASE +1 REF
C12: Global Element Size | D12: =E12*2 -> 0.001 | E12: 0.0005 | F12: =E12/$H$6 -> 0.00025
C13: Local Element Size | D13: =D12/SQRT(2) -> 0.00070710678 | E13: =E12/SQRT(2) -> 0.00035355339 | F13: =F12/SQRT(2) -> 0.0001767767
B14: Results | C14: yplusval | D14: 0.0944257 | E14: 3983051
C15: YplusMax | D15: 3.31464 | E15: 1186948
C16: WallShearMax | D16: 55.2322 | E16: 2.53729 | G16: 0.001
C17: WallShearAvg | D17: 1.04361 | E17: 0.698183 | G17: 0.000707107
C18: VelocityAvg | D18: 0.480079 | E18: 14804.8
C19: VelocityMax | D19: 1.38548 | E19: 16203.7
C20: PressureAvg | D20: 15500 | E20: 1.91189
C21: PressureMax | D21: 16076.4 | E21: 424.659
C22: Mesh Elements | D22: 749820 | E22: 7.69725
C23: No# Nodes | D23: 232893 | E23: 0.133912
B24: Results | C24: Mesh Elements | D24: 749820 | E24: 3983051 | F24: 22781658
C25: Mesh Nodes | D25: 232893 | E25: 1186948 | F25: 6098820
C26: VelocityMax3D | D26: 2.45723 | E26: 2.53729 | F26: 2.55705 | G26: m s^-1
C27: VelocityAvg3D | D27: 0.681712 | E27: 0.698183 | F27: 0.703475 | G27: m s^-1
C28: PressureAvg3D | D28: 14828 | E28: 14804.8 | F28: 14810 | G28: Pa
C29: PressureMax3D | D29: 16384.8 | E29: 16203.7 | F29: 16217.8 | G29: Pa
C30: WallShearAvg3D | D30: 2.17233 | E30: 1.91189 | F30: 2.602 | G30: Pa
C31: WallShearMax3D | D31: 403.893 | E31: 424.659 | F31: 548.196 | G31: Pa
C32: YplusMax3D | D32: 13.2491 | E32: 7.69725 | F32: 5.80777 | J32: Step 4 - find convergence errors of the various mesh, using the following equation
C33: YplusAvg3D | D33: 0.255544 | E33: 0.133912 | F33: 0.179148
C34: Sim Time | E34: 4 hours | F34: 49 hours
C36: (Max Velocity)
B37: phi_1 | C37: =F26 -> 2.55705
B38: phi_2 | C38: =E26 -> 2.53729
B39: phi_3 | C39: =D26 -> 2.45723
B40: p | C40: =(LN((C39-C38)/(C38-C37)))/(LN(H6)) -> 2.0184987
B42: Richardson Extrapolation | C42: =C37+((C37-C38)/((H6^C40) - 1)) -> 2.5635253
C45: Coarse | D45: Base | E45: Fine
B46: Convergence Error % | C46: =((C42-C39)/C42)*100 -> 4.1464483 | D46: =((C42-C38)/C42)*100 -> 1.0234052 | E46: =((C42-C37)/C42)*100 -> 0.25259164
B51: Processed Nodes# | C51: =(1/D25)/(10^-6) -> 4.2938173 | D51: =(1/E25)/(10^-6) -> 0.84249689 | E51: =(1/F25)/(10^-6) -> 0.16396614
...
